Workbook

Sheet connector_leads
A1: lead_id | B1: connector_id | C1: region | D1: segment | E1: product | F1: lead_date | G1: approved | H1: approved count | I1: disbursed | J1: disbursed count | K1: tat_days | L1: disbursal_amount
A2: LD10000 | B2: CN1005 | C2: Delhi NCR | D2: Direct Sales | E2: Personal Loan | F2: 46029 | G2: FALSE | H2: =--G2 -> 0 | I2: FALSE | J2: =--I2 -> 0 | L2: 0
A3: LD10001 | B3: CN1028 | C3: Mumbai | D3: Aggregator | E3: Home Loan | F3: 46080 | G3: TRUE | H3: =--G3 -> 1 | I3: TRUE | J3: =--I3 -> 1 | K3: 25 | L3: 2236000
A4: LD10002 | B4: CN1013 | C4: Chennai | D4: Aggregator | E4: Personal Loan | F4: 46131 | G4: TRUE | H4: =--G4 -> 1 | I4: TRUE | J4: =--I4 -> 1 | K4: 9 | L4: 1288000
A5: LD10003 | B5: CN1036 | C5: Hyderabad | D5: DSA | E5: Personal Loan | F5: 46166 | G5: TRUE | H5: =--G5 -> 1 | I5: TRUE | J5: =--I5 -> 1 | K5: 19 | L5: 1078000
A6: LD10004 | B6: CN1049 | C6: Pune | D6: Digital Partner | E6: Business Loan | F6: 46173 | G6: TRUE | H6: =--G6 -> 1 | I6: FALSE | J6: =--I6 -> 0 | K6: 7 | L6: 0
A7: LD10005 | B7: CN1023 | C7: Delhi NCR | D7: Digital Partner | E7: Business Loan | F7: 46110 | G7: TRUE | H7: =--G7 -> 1 | I7: TRUE | J7: =--I7 -> 1 | K7: 12 | L7: 300000
A8: LD10006 | B8: CN1014 | C8: Delhi NCR | D8: Aggregator | E8: Business Loan | F8: 46047 | G8: TRUE | H8: =--G8 -> 1 | I8: TRUE | J8: =--I8 -> 1 | K8: 10 | L8: 2027000
A9: LD10007 | B9: CN1059 | C9: Pune | D9: DSA | E9: Business Loan | F9: 46160 | G9: TRUE | H9: =--G9 -> 1 | I9: FALSE | J9: =--I9 -> 0 | K9: 4 | L9: 0
A10: LD10008 | B10: CN1053 | C10: Mumbai | D10: DSA | E10: LAP | F10: 46115 | G10: TRUE | H10: =--G10 -> 1 | I10: TRUE | J10: =--I10 -> 1 | K10: 3 | L10: 1670000
A11: LD10009 | B11: CN1057 | C11: Pune | D11: DSA | E11: LAP | F11: 46043 | G11: FALSE | H11: =--G11 -> 0 | I11: FALSE | J11: =--I11 -> 0 | L11: 0
A12: LD10010 | B12: CN1015 | C12: Pune | D12: Aggregator | E12: Personal Loan | F12: 46120 | G12: TRUE | H12: =--G12 -> 1 | I12: TRUE | J12: =--I12 -> 1 | K12: 13 | L12: 449000
A13: LD10011 | B13: CN1051 | C13: Delhi NCR | D13: DSA | E13: LAP | F13: 46076 | G13: FALSE | H13: =--G13 -> 0 | I13: FALSE | J13: =--I13 -> 0 | L13: 0
A14: LD10012 | B14: CN1040 | C14: Mumbai | D14: Digital Partner | E14: Personal Loan | F14: 46066 | G14: TRUE | H14: =--G14 -> 1 | I14: TRUE | J14: =--I14 -> 1 | K14: 16 | L14: 980000
A15: LD10013 | B15: CN1033 | C15: Pune | D15: Aggregator | E15: Home Loan | F15: 46106 | G15: FALSE | H15: =--G15 -> 0 | I15: FALSE | J15: =--I15 -> 0 | L15: 0
A16: LD10014 | B16: CN1031 | C16: Delhi NCR | D16: Direct Sales | E16: Personal Loan | F16: 46081 | G16: FALSE | H16: =--G16 -> 0 | I16: FALSE | J16: =--I16 -> 0 | L16: 0
A17: LD10015 | B17: CN1041 | C17: Bangalore | D17: DSA | E17: LAP | F17: 46125 | G17: TRUE | H17: =--G17 -> 1 | I17: TRUE | J17: =--I17 -> 1 | K17: 20 | L17: 2197000
A18: LD10016 | B18: CN1012 | C18: Hyderabad | D18: Aggregator | E18: LAP | F18: 46077 | G18: FALSE | H18: =--G18 -> 0 | I18: FALSE | J18: =--I18 -> 0 | L18: 0
A19: LD10017 | B19: CN1043 | C19: Bangalore | D19: Direct Sales | E19: Business Loan | F19: 46140 | G19: TRUE | H19: =--G19 -> 1 | I19: TRUE | J19: =--I19 -> 1 | K19: 25 | L19: 1425000
A20: LD10018 | B20: CN1007 | C20: Bangalore | D20: DSA | E20: LAP | F20: 46172 | G20: TRUE | H20: =--G20 -> 1 | I20: TRUE | J20: =--I20 -> 1 | K20: 13 | L20: 587000
A21: LD10019 | B21: CN1046 | C21: Delhi NCR | D21: Aggregator | E21: Home Loan | F21: 46153 | G21: TRUE | H21: =--G21 -> 1 | I21: TRUE | J21: =--I21 -> 1 | K21: 5 | L21: 424000
A22: LD10020 | B22: CN1038 | C22: Pune | D22: Digital Partner | E22: Home Loan | F22: 46131 | G22: TRUE | H22: =--G22 -> 1 | I22: TRUE | J22: =--I22 -> 1 | K22: 21 | L22: 2490000
A23: LD10021 | B23: CN1031 | C23: Delhi NCR | D23: Direct Sales | E23: LAP | F23: 46164 | G23: FALSE | H23: =--G23 -> 0 | I23: FALSE | J23: =--I23 -> 0 | L23: 0
A24: LD10022 | B24: CN1012 | C24: Hyderabad | D24: Aggregator | E24: Personal Loan | F24: 46052 | G24: FALSE | H24: =--G24 -> 0 | I24: FALSE | J24: =--I24 -> 0 | L24: 0
A25: LD10023 | B25: CN1037 | C25: Bangalore | D25: Aggregator | E25: LAP | F25: 46110 | G25: TRUE | H25: =--G25 -> 1 | I25: TRUE | J25: =--I25 -> 1 | K25: 16 | L25: 58000
A26: LD10024 | B26: CN1041 | C26: Bangalore | D26: DSA | E26: LAP | F26: 46151 | G26: FALSE | H26: =--G26 -> 0 | I26: FALSE | J26: =--I26 -> 0 | L26: 0
A27: LD10025 | B27: CN1006 | C27: Bangalore | D27: Aggregator | E27: Personal Loan | F27: 46099 | G27: FALSE | H27: =--G27 -> 0 | I27: FALSE | J27: =--I27 -> 0 | L27: 0
A28: LD10026 | B28: CN1052 | C28: Delhi NCR | D28: DSA | E28: Home Loan | F28: 46062 | G28: TRUE | H28: =--G28 -> 1 | I28: TRUE | J28: =--I28 -> 1 | K28: 18 | L28: 2300000
A29: LD10027 | B29: CN1012 | C29: Hyderabad | D29: Aggregator | E29: LAP | F29: 46148 | G29: TRUE | H29: =--G29 -> 1 | I29: FALSE | J29: =--I29 -> 0 | K29: 11 | L29: 0
A30: LD10028 | B30: CN1037 | C30: Bangalore | D30: Aggregator | E30: Home Loan | F30: 46037 | G30: TRUE | H30: =--G30 -> 1 | I30: TRUE | J30: =--I30 -> 1 | K30: 4 | L30: 260000
A31: LD10029 | B31: CN1049 | C31: Pune | D31: Digital Partner | E31: Business Loan | F31: 46040 | G31: FALSE | H31: =--G31 -> 0 | I31: FALSE | J31: =--I31 -> 0 | L31: 0
A32: LD10030 | B32: CN1036 | C32: Hyderabad | D32: DSA | E32: Home Loan | F32: 46055 | G32: FALSE | H32: =--G32 -> 0 | I32: FALSE | J32: =--I32 -> 0 | L32: 0
A33: LD10031 | B33: CN1012 | C33: Hyderabad | D33: Aggregator | E33: Home Loan | F33: 46090 | G33: FALSE | H33: =--G33 -> 0 | I33: FALSE | J33: =--I33 -> 0 | L33: 0
A34: LD10032 | B34: CN1033 | C34: Pune | D34: Aggregator | E34: Business Loan | F34: 46077 | G34: FALSE | H34: =--G34 -> 0 | I34: FALSE | J34: =--I34 -> 0 | L34: 0
A35: LD10033 | B35: CN1015 | C35: Pune | D35: Aggregator | E35: Home Loan | F35: 46102 | G35: TRUE | H35: =--G35 -> 1 | I35: TRUE | J35: =--I35 -> 1 | K35: 13 | L35: 1123000
A36: LD10034 | B36: CN1056 | C36: Delhi NCR | D36: DSA | E36: Business Loan | F36: 46053 | G36: TRUE | H36: =--G36 -> 1 | I36: TRUE | J36: =--I36 -> 1 | K36: 2 | L36: 1491000
A37: LD10035 | B37: CN1012 | C37: Hyderabad | D37: Aggregator | E37: Home Loan | F37: 46173 | G37: TRUE | H37: =--G37 -> 1 | I37: TRUE | J37: =--I37 -> 1 | K37: 22 | L37: 194000
A38: LD10036 | B38: CN1041 | C38: Bangalore | D38: DSA | E38: Personal Loan | F38: 46031 | G38: FALSE | H38: =--G38 -> 0 | I38: FALSE | J38: =--I38 -> 0 | L38: 0
A39: LD10037 | B39: CN1054 | C39: Delhi NCR | D39: Direct Sales | E39: Personal Loan | F39: 46154 | G39: TRUE | H39: =--G39 -> 1 | I39: TRUE | J39: =--I39 -> 1 | K39: 8 | L39: 1371000
A40: LD10038 | B40: CN1017 | C40: Hyderabad | D40: Digital Partner | E40: Business Loan | F40: 46085 | G40: FALSE | H40: =--G40 -> 0 | I40: FALSE | J40: =--I40 -> 0 | L40: 0
...

Sheet Region Funnel
A1: Region-wise Sales Funnel
E2: Conversion%
E3: =D3/B3 -> 0.56670602
E4: =D4/B4 -> 0.28144458
E5: =D5/B5 -> 0.52707581
E6: =D6/B6 -> 0.53313697
E7: =D7/B7 -> 0.49489796
E8: =D8/B8 -> 0.49600639

Sheet Product Funnel
A1: Product-wise Sales Funnel
E2: Conversion%
E3: =D3/B3 -> 0.48224152
E4: =D4/B4 -> 0.47662018
E5: =D5/B5 -> 0.49115756
E6: =D6/B6 -> 0.48425197

Sheet Segment Funnel
A1: Segment-wise Sales Funnel
E2: Conversion%
E3: =D3/B3 -> 0.39248434
E4: =D4/B4 -> 0.51939058
E5: =D5/B5 -> 0.51422071
E6: =D6/B6 -> 0.52580645

Sheet Connector Scorecard
A1: Connector Scorecard
A2: Connector ID | B2: Region | C2: Segment | D2: Total Leads | E2: Total Approvals | F2: Total Disbursal | G2: Conversion% | H2: Performance Flag
A3: CN1005 | B3: {=XLOOKUP(A3,connector_leads!B2:B5001,connector_leads!C2:C5001)} -> Delhi NCR | C3: {=XLOOKUP(A3,connector_leads!B2:B5001,connector_leads!D2:D5001)} -> Direct Sales | D3: =COUNTIF(connector_leads!B2:B5001,A3) -> 79 | E3: =SUMIFS(connector_leads!H2:H5001,connector_leads!B2:B5001,A3) -> 53 | F3: =SUMIFS(connector_leads!J2:J5001,connector_leads!B2:B5001,A3) -> 50 | G3: =F3/D3 -> 0.63291139 | H3: =IFS(G3<0.4,"Needs Attention",G3<0.55,"Average",G3>=0.55,"Strong") -> Strong
A4: CN1028 | B4: {=XLOOKUP(A4,connector_leads!B3:B5002,connector_leads!C3:C5002)} -> Mumbai | C4: {=XLOOKUP(A4,connector_leads!B3:B5002,connector_leads!D3:D5002)} -> Aggregator | D4: =COUNTIF(connector_leads!B3:B5002,A4) -> 59 | E4: =SUMIFS(connector_leads!H3:H5002,connector_leads!B3:B5002,A4) -> 30 | F4: =SUMIFS(connector_leads!J3:J5002,connector_leads!B3:B5002,A4) -> 24 | G4: =F4/D4 -> 0.40677966 | H4: =IFS(G4<0.4,"Needs Attention",G4<0.55,"Average",G4>=0.55,"Strong") -> Average
A5: CN1013 | B5: {=XLOOKUP(A5,connector_leads!B4:B5003,connector_leads!C4:C5003)} -> Chennai | C5: {=XLOOKUP(A5,connector_leads!B4:B5003,connector_leads!D4:D5003)} -> Aggregator | D5: =COUNTIF(connector_leads!B4:B5003,A5) -> 67 | E5: =SUMIFS(connector_leads!H4:H5003,connector_leads!B4:B5003,A5) -> 18 | F5: =SUMIFS(connector_leads!J4:J5003,connector_leads!B4:B5003,A5) -> 15 | G5: =F5/D5 -> 0.2238806 | H5: =IFS(G5<0.4,"Needs Attention",G5<0.55,"Average",G5>=0.55,"Strong") -> Needs Attention
A6: CN1036 | B6: {=XLOOKUP(A6,connector_leads!B5:B5004,connector_leads!C5:C5004)} -> Hyderabad | C6: {=XLOOKUP(A6,connector_leads!B5:B5004,connector_leads!D5:D5004)} -> DSA | D6: =COUNTIF(connector_leads!B5:B5004,A6) -> 88 | E6: =SUMIFS(connector_leads!H5:H5004,connector_leads!B5:B5004,A6) -> 56 | F6: =SUMIFS(connector_leads!J5:J5004,connector_leads!B5:B5004,A6) -> 48 | G6: =F6/D6 -> 0.54545455 | H6: =IFS(G6<0.4,"Needs Attention",G6<0.55,"Average",G6>=0.55,"Strong") -> Average
A7: CN1049 | B7: {=XLOOKUP(A7,connector_leads!B6:B5005,connector_leads!C6:C5005)} -> Pune | C7: {=XLOOKUP(A7,connector_leads!B6:B5005,connector_leads!D6:D5005)} -> Digital Partner | D7: =COUNTIF(connector_leads!B6:B5005,A7) -> 90 | E7: =SUMIFS(connector_leads!H6:H5005,connector_leads!B6:B5005,A7) -> 53 | F7: =SUMIFS(connector_leads!J6:J5005,connector_leads!B6:B5005,A7) -> 41 | G7: =F7/D7 -> 0.45555556 | H7: =IFS(G7<0.4,"Needs Attention",G7<0.55,"Average",G7>=0.55,"Strong") -> Average
A8: CN1023 | B8: {=XLOOKUP(A8,connector_leads!B7:B5006,connector_leads!C7:C5006)} -> Delhi NCR | C8: {=XLOOKUP(A8,connector_leads!B7:B5006,connector_leads!D7:D5006)} -> Digital Partner | D8: =COUNTIF(connector_leads!B7:B5006,A8) -> 88 | E8: =SUMIFS(connector_leads!H7:H5006,connector_leads!B7:B5006,A8) -> 52 | F8: =SUMIFS(connector_leads!J7:J5006,connector_leads!B7:B5006,A8) -> 43 | G8: =F8/D8 -> 0.48863636 | H8: =IFS(G8<0.4,"Needs Attention",G8<0.55,"Average",G8>=0.55,"Strong") -> Average
A9: CN1014 | B9: {=XLOOKUP(A9,connector_leads!B8:B5007,connector_leads!C8:C5007)} -> Delhi NCR | C9: {=XLOOKUP(A9,connector_leads!B8:B5007,connector_leads!D8:D5007)} -> Aggregator | D9: =COUNTIF(connector_leads!B8:B5007,A9) -> 70 | E9: =SUMIFS(connector_leads!H8:H5007,connector_leads!B8:B5007,A9) -> 41 | F9: =SUMIFS(connector_leads!J8:J5007,connector_leads!B8:B5007,A9) -> 32 | G9: =F9/D9 -> 0.45714286 | H9: =IFS(G9<0.4,"Needs Attention",G9<0.55,"Average",G9>=0.55,"Strong") -> Average
A10: CN1059 | B10: {=XLOOKUP(A10,connector_leads!B9:B5008,connector_leads!C9:C5008)} -> Pune | C10: {=XLOOKUP(A10,connector_leads!B9:B5008,connector_leads!D9:D5008)} -> DSA | D10: =COUNTIF(connector_leads!B9:B5008,A10) -> 78 | E10: =SUMIFS(connector_leads!H9:H5008,connector_leads!B9:B5008,A10) -> 48 | F10: =SUMIFS(connector_leads!J9:J5008,connector_leads!B9:B5008,A10) -> 42 | G10: =F10/D10 -> 0.53846154 | H10: =IFS(G10<0.4,"Needs Attention",G10<0.55,"Average",G10>=0.55,"Strong") -> Average
A11: CN1053 | B11: {=XLOOKUP(A11,connector_leads!B10:B5009,connector_leads!C10:C5009)} -> Mumbai | C11: {=XLOOKUP(A11,connector_leads!B10:B5009,connector_leads!D10:D5009)} -> DSA | D11: =COUNTIF(connector_leads!B10:B5009,A11) -> 95 | E11: =SUMIFS(connector_leads!H10:H5009,connector_leads!B10:B5009,A11) -> 54 | F11: =SUMIFS(connector_leads!J10:J5009,connector_leads!B10:B5009,A11) -> 48 | G11: =F11/D11 -> 0.50526316 | H11: =IFS(G11<0.4,"Needs Attention",G11<0.55,"Average",G11>=0.55,"Strong") -> Average
A12: CN1057 | B12: {=XLOOKUP(A12,connector_leads!B11:B5010,connector_leads!C11:C5010)} -> Pune | C12: {=XLOOKUP(A12,connector_leads!B11:B5010,connector_leads!D11:D5010)} -> DSA | D12: =COUNTIF(connector_leads!B11:B5010,A12) -> 70 | E12: =SUMIFS(connector_leads!H11:H5010,connector_leads!B11:B5010,A12) -> 49 | F12: =SUMIFS(connector_leads!J11:J5010,connector_leads!B11:B5010,A12) -> 40 | G12: =F12/D12 -> 0.57142857 | H12: =IFS(G12<0.4,"Needs Attention",G12<0.55,"Average",G12>=0.55,"Strong") -> Strong
A13: CN1015 | B13: {=XLOOKUP(A13,connector_leads!B12:B5011,connector_leads!C12:C5011)} -> Pune | C13: {=XLOOKUP(A13,connector_leads!B12:B5011,connector_leads!D12:D5011)} -> Aggregator | D13: =COUNTIF(connector_leads!B12:B5011,A13) -> 94 | E13: =SUMIFS(connector_leads!H12:H5011,connector_leads!B12:B5011,A13) -> 50 | F13: =SUMIFS(connector_leads!J12:J5011,connector_leads!B12:B5011,A13) -> 42 | G13: =F13/D13 -> 0.44680851 | H13: =IFS(G13<0.4,"Needs Attention",G13<0.55,"Average",G13>=0.55,"Strong") -> Average
A14: CN1051 | B14: {=XLOOKUP(A14,connector_leads!B13:B5012,connector_leads!C13:C5012)} -> Delhi NCR | C14: {=XLOOKUP(A14,connector_leads!B13:B5012,connector_leads!D13:D5012)} -> DSA | D14: =COUNTIF(connector_leads!B13:B5012,A14) -> 84 | E14: =SUMIFS(connector_leads!H13:H5012,connector_leads!B13:B5012,A14) -> 53 | F14: =SUMIFS(connector_leads!J13:J5012,connector_leads!B13:B5012,A14) -> 44 | G14: =F14/D14 -> 0.52380952 | H14: =IFS(G14<0.4,"Needs Attention",G14<0.55,"Average",G14>=0.55,"Strong") -> Average
... A62: CN1016 | B62: {=XLOOKUP(A62,connector_leads!B61:B5060,connector_leads!C61:C5060)} -> Hyderabad | C62: {=XLOOKUP(A62,connector_leads!B61:B5060,connector_leads!D61:D5060)} -> Aggregator | D62: =COUNTIF(connector_leads!B61:B5060,A62) -> 87 | E62: =SUMIFS(connector_leads!H61:H5060,connector_leads!B61:B5060,A62) -> 42 | F62: =SUMIFS(connector_leads!J61:J5060,connector_leads!B61:B5060,A62) -> 35 | G62: =F62/D62 -> 0.40229885 | H62: =IFS(G62<0.4,"Needs Attention",G62<0.55,"Average",G62>=0.55,"Strong") -> Average
